(In r20398) Fixed scala/bug#2850 -- while inside finally causes VerifyError, review by rytz
