I get a spurious warning "catch block may intercept non-local return from method check", but it only catches specific exceptions:

```scala
  def foo() {
    try {
      for (i <- 1 until 5) return
    } catch {
      case _: NullPointerException | _: RuntimeException =>
    }
  }
```
